
<robot name="onshape">

<!-- I ADDED THIS-->
<gazebo>
  <plugin name="gazebo_ros_control" filename="libgazebo_ros_control.so">
    <robotNamespace>/frcrobot_jetson</robotNamespace>
  </plugin>
</gazebo>

<link name="base_link"></link>
<joint name="base_link_to_base" type="fixed">
<parent link="base_link"/>
<child link="central_chassis" />
<origin rpy="0.0 0 0" xyz="0 0 0"/>
</joint>
<link name="central_chassis">
<visual>
<origin xyz="0 0 0" rpy="0 -0 0" />
<geometry>
<mesh filename="package://chimera_description/y2023_urdf/central_chassis_visual.stl"/>
</geometry>
<material name="central_chassis_material">
<color rgba="0.59658581071440275334 0.62025664106601530179 0.63761838421033922852 1.0"/>
</material>
</visual>
<collision>
<origin xyz="0 0 0" rpy="0 -0 0" />
<geometry>
<mesh filename="package://chimera_description/y2023_urdf/central_chassis_collision.stl"/>
</geometry>
</collision>
<inertial>
<origin xyz="-0.0019273005368478602836 0.086159516777112268859 0.32950095935230000466" rpy="0 0 0"/>
<mass value="7.7787891582795740675" />
<inertia ixx="0.69204932194372226206" ixy="0.0020725732451341441834"  ixz="-0.00019563921735660358327" iyy="0.61874181701311536941" iyz="0.11955242865535581354" izz="0.43424100425481687582" />
</inertial>
</link>


<link name="fixed_stage">
<visual>
<origin xyz="0 0 0" rpy="0 -0 0" />
<geometry>
<mesh filename="package://chimera_description/y2023_urdf/fixed_stage_visual.stl"/>
</geometry>
<material name="fixed_stage_material">
<color rgba="0.40580203232839273664 0.41204827568174384744 0.42591498950989253869 1.0"/>
</material>
</visual>
<collision>
<origin xyz="0 0 0" rpy="0 -0 0" />
<geometry>
<mesh filename="package://chimera_description/y2023_urdf/fixed_stage_collision.stl"/>
</geometry>
</collision>
<inertial>
<origin xyz="0.093086953924054083309 -0.0076968875686334835284 0.0064477325071934680698" rpy="0 0 0"/>
<mass value="2.1102377118679833679" />
<inertia ixx="0.0072740667010466790801" ixy="-0.00053724169913203041402"  ixz="0.0025793419797913606437" iyy="0.010711313332956690081" iyz="-0.00048364111011172229802" izz="0.0072293168828333554191" />
</inertial>
</link>

<link name="first_stage">
<visual>
<origin xyz="0 0 0" rpy="0 -0 0" />
<geometry>
<mesh filename="package://chimera_description/y2023_urdf/first_stage_visual.stl"/>
</geometry>
<material name="first_stage_material">
<color rgba="0.62679849529055442492 0.64535024166481913532 0.68477270271013190861 1.0"/>
</material>
</visual>
<collision>
<origin xyz="0 0 0" rpy="0 -0 0" />
<geometry>
<mesh filename="package://chimera_description/y2023_urdf/first_stage_collision.stl"/>
</geometry>
</collision>
<inertial>
<origin xyz="0.0006576109478568944143 0.00065772624260732796917 0.013546669400210403778" rpy="0 0 0"/>
<mass value="0.37485540355657043232" />
<inertia ixx="0.00039226399064708574772" ixy="-8.0584943533433742841e-05"  ixz="2.2105941443719435968e-05" iyy="0.00039226841599643508599" iyz="2.2036140493595741198e-05" izz="0.00038236676743388893019" />
</inertial>
</link>

<link name="second_stage">
<visual>
<origin xyz="0 0 0" rpy="0 -0 0" />
<geometry>
<mesh filename="package://chimera_description/y2023_urdf/second_stage_visual.stl"/>
</geometry>
<material name="second_stage_material">
<color rgba="0.43962129049865944497 0.48422362538019192435 0.58086036059590284708 1.0"/>
</material>
</visual>
<collision>
<origin xyz="0 0 0" rpy="0 -0 0" />
<geometry>
<mesh filename="package://chimera_description/y2023_urdf/second_stage_collision.stl"/>
</geometry>
</collision>
<inertial>
<origin xyz="-0.00060219608071355264136 -0.00042989751734581114996 -0.025814159072832135872" rpy="0 0 0"/>
<mass value="0.34193546654456352663" />
<inertia ixx="0.00025919001370537073136" ixy="-4.3830553719887962042e-06"  ixz="9.5090523028358471603e-07" iyy="0.00026221580444056911225" iyz="6.7704477026286145322e-07" izz="0.00043171455134411156757" />
</inertial>
</link>

<joint name="left_front_drive_wheel" type="continuous">
<origin xyz="-0.014718639782432818564 -0.014718639782432485497 0.041331499999999611605" rpy="1.5707963267948974462 0.3547103969677229407 -0.78539816339744616958" />
<parent link="first_stage" />
<child link="second_stage" />
<axis xyz="0 0 1"/>
<limit effort="1" velocity="20" />
<joint_properties friction="0.0"/>
</joint>

<joint name="left_front_angle_wheel" type="continuous">
<origin xyz="0.066674999999999984279 0.0075565000000000354108 -0.019843749999999937828" rpy="-1.5707963267948954478 -0.0013042609915997001487 -9.0564346581562362991e-16" />
<parent link="fixed_stage" />
<child link="first_stage" />
<axis xyz="0 0 1"/>
<limit effort="1" velocity="20" />
<joint_properties friction="0.0"/>
</joint>

<transmission name="simple_trans">
  <type>transmission_interface/SimpleTransmission</type>
  <joint name="left_front_angle_wheel">
    <hardwareInterface>hardware_interface/PositionJointInterface</hardwareInterface>
  </joint>
  <actuator name="foo_motor">
    <mechanicalReduction>1</mechanicalReduction>
    <hardwareInterface>hardware_interface/PositionJointInterface</hardwareInterface>
  </actuator>
</transmission>

<joint name="XX1_center" type="fixed">
<origin xyz="-0.23098760000000007064 0.31750000000000000444 0.097205800000000008865" rpy="-1.570796326794896558 -0 -1.570796326794896558" />
<parent link="central_chassis" />
<child link="fixed_stage" />
<axis xyz="0 0 1"/>
<limit effort="1" velocity="20" />
<joint_properties friction="0.0"/>
</joint>

<link name="fixed_stage_2">
<visual>
<origin xyz="0 0 0" rpy="0 -0 0" />
<geometry>
<mesh filename="package://chimera_description/y2023_urdf/fixed_stage_2_visual.stl"/>
</geometry>
<material name="fixed_stage_2_material">
<color rgba="0.40580203232839251459 0.41204827568174356989 0.42591498950989220562 1.0"/>
</material>
</visual>
<collision>
<origin xyz="0 0 0" rpy="0 -0 0" />
<geometry>
<mesh filename="package://chimera_description/y2023_urdf/fixed_stage_2_collision.stl"/>
</geometry>
</collision>
<inertial>
<origin xyz="0.093086953924053972287 -0.0076968875686333568936 0.0064477325071934498552" rpy="0 0 0"/>
<mass value="2.1102377118679847001" />
<inertia ixx="0.0072740667010466868864" ixy="-0.00053724169913203713607"  ixz="0.0025793419797913485006" iyy="0.01071131333295669702" iyz="-0.0004836411101117270143" izz="0.0072293168828333545517" />
</inertial>
</link>

<link name="first_stage_2">
<visual>
<origin xyz="0 0 0" rpy="0 -0 0" />
<geometry>
<mesh filename="package://chimera_description/y2023_urdf/first_stage_2_visual.stl"/>
</geometry>
<material name="first_stage_2_material">
<color rgba="0.62679849529055420287 0.6453502416648190243 0.68477270271013190861 1.0"/>
</material>
</visual>
<collision>
<origin xyz="0 0 0" rpy="0 -0 0" />
<geometry>
<mesh filename="package://chimera_description/y2023_urdf/first_stage_2_collision.stl"/>
</geometry>
</collision>
<inertial>
<origin xyz="0.00065761094785723344432 0.00065772624260738087824 0.013546669400210662251" rpy="0 0 0"/>
<mass value="0.37485540355657048783" />
<inertia ixx="0.00039226399064709116873" ixy="-8.0584943533433797051e-05"  ixz="2.2105941443718250122e-05" iyy="0.00039226841599643974805" iyz="2.2036140493596303628e-05" izz="0.00038236676743388990597" />
</inertial>
</link>

<link name="second_stage_2">
<visual>
<origin xyz="0 0 0" rpy="0 -0 0" />
<geometry>
<mesh filename="package://chimera_description/y2023_urdf/second_stage_2_visual.stl"/>
</geometry>
<material name="second_stage_2_material">
<color rgba="0.43962129049865938946 0.48422362538019181333 0.58086036059590284708 1.0"/>
</material>
</visual>
<collision>
<origin xyz="0 0 0" rpy="0 -0 0" />
<geometry>
<mesh filename="package://chimera_description/y2023_urdf/second_stage_2_collision.stl"/>
</geometry>
</collision>
<inertial>
<origin xyz="-0.00060219608071357150648 -0.00042989751734580659631 -0.025814159072832104647" rpy="0 0 0"/>
<mass value="0.34193546654456352663" />
<inertia ixx="0.00025919001370537067715" ixy="-4.3830553719887775695e-06"  ixz="9.5090523028352595312e-07" iyy="0.00026221580444056905804" iyz="6.7704477026275186833e-07" izz="0.00043171455134411156757" />
</inertial>
</link>

<joint name="left_back_drive_wheel" type="continuous">
<origin xyz="-0.014718639782431541807 -0.014718639782432388352 0.041331500000000201411" rpy="1.5707963267948981123 -0.10233292597333981666 -0.78539816339744639162" />
<parent link="first_stage_2" />
<child link="second_stage_2" />
<axis xyz="0 0 1"/>
<limit effort="1" velocity="20" />
<joint_properties friction="0.0"/>
</joint>

<joint name="left_back_angle_wheel" type="continuous">
<origin xyz="0.06667500000000003979 0.007556500000000021533 -0.019843749999999965583" rpy="1.570796326794896558 0.74446276911887487859 3.141592653589793116" />
<parent link="fixed_stage_2" />
<child link="first_stage_2" />
<axis xyz="0 0 1"/>
<limit effort="1" velocity="20" />
<joint_properties friction="0.0"/>
</joint>

<joint name="XX2_center" type="fixed">
<origin xyz="-0.31750000000000011546 -0.23098760000000001513 0.097205800000000008865" rpy="-1.570796326794896558 2.8471472759711992776e-46 -1.7483827159451257974e-16" />
<parent link="central_chassis" />
<child link="fixed_stage_2" />
<axis xyz="0 0 1"/>
<limit effort="1" velocity="20" />
<joint_properties friction="0.0"/>
</joint>

<link name="fixed_stage_3">
<visual>
<origin xyz="0 0 0" rpy="0 -0 0" />
<geometry>
<mesh filename="package://chimera_description/y2023_urdf/fixed_stage_3_visual.stl"/>
</geometry>
<material name="fixed_stage_3_material">
<color rgba="0.40580203232839245908 0.41204827568174368091 0.42591498950989231664 1.0"/>
</material>
</visual>
<collision>
<origin xyz="0 0 0" rpy="0 -0 0" />
<geometry>
<mesh filename="package://chimera_description/y2023_urdf/fixed_stage_3_collision.stl"/>
</geometry>
</collision>
<inertial>
<origin xyz="-0.092585482507193353485 -0.007315887568633472858 0.0065682039240540267613" rpy="0 0 0"/>
<mass value="2.110237711867984256" />
<inertia ixx="0.0072293168828333580211" ixy="0.00048364111011172045487"  ixz="-0.0025793419797913610773" iyy="0.010711313332956684877" iyz="-0.00053724169913202987191" izz="0.0072740667010466799475" />
</inertial>
</link>

<link name="first_stage_3">
<visual>
<origin xyz="0 0 0" rpy="0 -0 0" />
<geometry>
<mesh filename="package://chimera_description/y2023_urdf/first_stage_3_visual.stl"/>
</geometry>
<material name="first_stage_3_material">
<color rgba="0.6267984952905543139 0.64535024166481924635 0.68477270271013201963 1.0"/>
</material>
</visual>
<collision>
<origin xyz="0 0 0" rpy="0 -0 0" />
<geometry>
<mesh filename="package://chimera_description/y2023_urdf/first_stage_3_collision.stl"/>
</geometry>
</collision>
<inertial>
<origin xyz="0.0018255910263494014995 0.0018257063211000476664 0.01354666940020976193" rpy="0 0 0"/>
<mass value="0.37485540355657043232" />
<inertia ixx="0.00039226399064707913409" ixy="-8.0584943533434298495e-05"  ixz="2.2105941443719026004e-05" iyy="0.0003922684159964287434" iyz="2.2036140493595005973e-05" izz="0.00038236676743388681599" />
</inertial>
</link>

<link name="second_stage_3">
<visual>
<origin xyz="0 0 0" rpy="0 -0 0" />
<geometry>
<mesh filename="package://chimera_description/y2023_urdf/second_stage_3_visual.stl"/>
</geometry>
<material name="second_stage_3_material">
<color rgba="0.43962129049865944497 0.48422362538019192435 0.58086036059590284708 1.0"/>
</material>
</visual>
<collision>
<origin xyz="0 0 0" rpy="0 -0 0" />
<geometry>
<mesh filename="package://chimera_description/y2023_urdf/second_stage_3_collision.stl"/>
</geometry>
</collision>
<inertial>
<origin xyz="-0.0006021960807134611347 -0.000429897517345806 -0.025814159072832170566" rpy="0 0 0"/>
<mass value="0.34193546654456352663" />
<inertia ixx="0.00025919001370537089399" ixy="-4.3830553719887775695e-06"  ixz="9.5090523028371526499e-07" iyy="0.0002622158044405693833" iyz="6.7704477026274000987e-07" izz="0.00043171455134411135073" />
</inertial>
</link>

<joint name="right_back_drive_wheel" type="continuous">
<origin xyz="-0.013550659703940370893 -0.013550659703939815781 0.041331499999998508321" rpy="-1.5707963267948952257 -0.38629807207531591251 2.3561944901923501661" />
<parent link="first_stage_3" />
<child link="second_stage_3" />
<axis xyz="0 0 1"/>
<limit effort="1" velocity="20" />
<joint_properties friction="0.0"/>
</joint>

<joint name="right_back_angle_wheel" type="continuous">
<origin xyz="-0.066293999999999908557 0.0079375000000000278666 -0.019843749999999937828" rpy="1.570796326794896558 -1.3713290209023065724 3.1415926535897726879" />
<parent link="fixed_stage_3" />
<child link="first_stage_3" />
<axis xyz="0 0 1"/>
<limit effort="1" velocity="20" />
<joint_properties friction="0.0"/>
</joint>

<joint name="XX3_center" type="fixed">
<origin xyz="0.31749999999999983791 -0.23098760000000001513 0.097205800000000008865" rpy="-1.570796326794896558 -0 -1.7483827159451285091e-16" />
<parent link="central_chassis" />
<child link="fixed_stage_3" />
<axis xyz="0 0 1"/>
<limit effort="1" velocity="20" />
<joint_properties friction="0.0"/>
</joint>

<link name="fixed_stage_4">
<visual>
<origin xyz="0 0 0" rpy="0 -0 0" />
<geometry>
<mesh filename="package://chimera_description/y2023_urdf/fixed_stage_4_visual.stl"/>
</geometry>
<material name="fixed_stage_4_material">
<color rgba="0.4058020323283925701 0.41204827568174368091 0.42591498950989242767 1.0"/>
</material>
</visual>
<collision>
<origin xyz="0 0 0" rpy="0 -0 0" />
<geometry>
<mesh filename="package://chimera_description/y2023_urdf/fixed_stage_4_collision.stl"/>
</geometry>
</collision>
<inertial>
<origin xyz="0.092705953924053882687 0.0073158875686334459698 -0.0064477325071933900072" rpy="0 0 0"/>
<mass value="2.110237711867984256" />
<inertia ixx="0.0072740667010466738759" ixy="0.00053724169913202846245"  ixz="-0.0025793419797913593426" iyy="0.010711313332956676203" iyz="-0.00048364111011172040066" izz="0.0072293168828333493475" />
</inertial>
</link>

<link name="first_stage_4">
<visual>
<origin xyz="0 0 0" rpy="0 -0 0" />
<geometry>
<mesh filename="package://chimera_description/y2023_urdf/first_stage_4_visual.stl"/>
</geometry>
<material name="first_stage_4_material">
<color rgba="0.62679849529055420287 0.6453502416648190243 0.68477270271013179759 1.0"/>
</material>
</visual>
<collision>
<origin xyz="0 0 0" rpy="0 -0 0" />
<geometry>
<mesh filename="package://chimera_description/y2023_urdf/first_stage_4_collision.stl"/>
</geometry>
</collision>
<inertial>
<origin xyz="0.00065761094785712274728 0.00065772624260720914061 0.013546669400210589393" rpy="0 0 0"/>
<mass value="0.37485540355657048783" />
<inertia ixx="0.000392263990647090464" ixy="-8.058494353343330916e-05"  ixz="2.2105941443718321273e-05" iyy="0.00039226841599643866385" iyz="2.2036140493596635665e-05" izz="0.00038236676743388914703" />
</inertial>
</link>

<link name="second_stage_4">
<visual>
<origin xyz="0 0 0" rpy="0 -0 0" />
<geometry>
<mesh filename="package://chimera_description/y2023_urdf/second_stage_4_visual.stl"/>
</geometry>
<material name="second_stage_4_material">
<color rgba="0.43962129049865944497 0.48422362538019197986 0.58086036059590284708 1.0"/>
</material>
</visual>
<collision>
<origin xyz="0 0 0" rpy="0 -0 0" />
<geometry>
<mesh filename="package://chimera_description/y2023_urdf/second_stage_4_collision.stl"/>
</geometry>
</collision>
<inertial>
<origin xyz="-0.00060219608071353724569 -0.00042989751734580247634 -0.025814159072832139341" rpy="0 0 0"/>
<mass value="0.34193546654456352663" />
<inertia ixx="0.00025919001370537062294" ixy="-4.383055371988789428e-06"  ixz="9.509052302835286001e-07" iyy="0.00026221580444056900383" iyz="6.7704477026273386888e-07" izz="0.00043171455134411140494" />
</inertial>
</link>

<joint name="right_front_drive_wheel" type="continuous">
<origin xyz="-0.014718639782432263452 -0.014718639782432541008 0.041331500000000041817" rpy="-1.5707963267948994446 0.53105430610586668028 2.3561944901923461693" />
<parent link="first_stage_4" />
<child link="second_stage_4" />
<axis xyz="0 0 1"/>
<limit effort="1" velocity="20" />
<joint_properties friction="0.0"/>
</joint>

<joint name="right_front_angle_wheel" type="continuous">
<origin xyz="0.066293999999999908557 -0.0079375000000000972555 0.019843750000000076605" rpy="-1.570796326794896558 1.2358944559116720185 3.141592653589793116" />
<parent link="fixed_stage_4" />
<child link="first_stage_4" />
<axis xyz="0 0 1"/>
<limit effort="1" velocity="20" />
<joint_properties friction="0.0"/>
</joint>

<joint name="XX4_center" type="fixed">
<origin xyz="0.31749999999999989342 0.23098759999999995962 0.097205800000000092131" rpy="1.570796326794896558 -2.2204460492411462706e-16 3.141592653589793116" />
<parent link="central_chassis" />
<child link="fixed_stage_4" />
<axis xyz="0 0 1"/>
<limit effort="1" velocity="20" />
<joint_properties friction="0.0"/>
</joint>


</robot>
