<?xml version="1.0"?>
<robot name="visual">

<material name="blue">
    <color rgba="0 0 0.8 1"/>
  </material>
  <material name="black">
    <color rgba="0 0 0 1"/>
  </material>
  <material name="white">
    <color rgba="1 1 1 1"/>
  </material>

  <link name="base_link">
  </link>

  <link name="head">
  </link>

  <joint name="turret_joint" type="continuous">
    <parent link="base_link"/>
    <child link="head"/>
    <axis xyz="0 0 1"/>
    <origin xyz="0 0 0.0"/>
  </joint>

  <link name="box">
    <visual>
      <geometry>
        <mesh filename="package://turret_2023/meshes/CITRUS_TURRET_HOOD.dae"/>
      </geometry>
    </visual>
  </link>

  <joint name="tobox" type="fixed">
    <parent link="head"/>
    <child link="box"/>
    <origin xyz="0.0 0 0.0"/>
  </joint>

  <joint name="to_field" type="fixed">
    <parent link="base_link"/>
    <child link="full_field"/>
    <origin xyz="0.0 0 0.0"/>
  </joint>

  <link name="full_field">
    <parent link="base_link"/>
    <visual>
      <origin rpy="0.0 0 0" xyz="0 0 0"/>
      <geometry>
        <mesh filename="package://turret_2023/meshes/MINIFRC_FIELD.dae"/>
      </geometry>
    </visual>
  </link>


</robot>
