<?xml version="1.0"?>
<robot name="sim">

<material name="blue">
    <color rgba="0 0 0.8 1"/>
</material>
<material name="white">
    <color rgba="1 1 1 1"/>
</material>

    <link name="base_link">
        <visual>
            <geometry>
                <box size=".1 .8 .4"/>
            </geometry>
            
            <material name="white"/>
        </visual>
    </link>

    <link name="left_top">
        <visual>
            <geometry>
                <box size=".1 .8 .4"/>
            </geometry>
            <material name="blue"/>
            <origin xyz="0 .4 0" />
        </visual>
    </link>

   <joint name="left_connection" type="continuous">
        <parent link="base_link"/>
        <child link="left_top"/>
        <origin xyz="0 .4 0"/>
        <axis xyz="0 0 1" rpy="1.57 0 0" />
        <calibration rising="2.0"/>
    </joint>
</robot>