<robot name="onshape">
<link name="base_link"></link>
<joint name="base_link_to_base" type="fixed">
<parent link="base_link"/>
<child link="central_chassis" />
<origin rpy="0.0 0 0" xyz="0 0 0"/>
</joint>
<link name="central_chassis">
<visual>
<origin xyz="0 0 0" rpy="0 -0 0" />
<geometry>
<mesh filename="package://frcrobot_description/meshes/central_chassis_visual.stl"/>
</geometry>
<material name="central_chassis_material">
<color rgba="0.59658581071440275334 0.62025664106601530179 0.63761838421033933955 1.0"/>
</material>
</visual>
<collision>
<origin xyz="0 0 0" rpy="0 -0 0" />
<geometry>
<mesh filename="package://frcrobot_description/meshes/central_chassis_collision.stl"/>
</geometry>
</collision>
<inertial>
<origin xyz="-0.0019273005368478318775 0.078247840542276278497 0.34320438456409596562" rpy="0 0 0"/>
<mass value="7.7787891582795776202" />
<inertia ixx="0.75435902139317201343" ixy="0.002243375292267710177"  ixz="-0.00049147704102887900847" iyy="0.67128335978412745355" iyz="5.04317933741828411942" izz="0.44400916093339543034" />
</inertial>
</link>

<link name="br_fixed_link">
<visual>
<origin xyz="0 0 0" rpy="0 -0 0" />
<geometry>
<mesh filename="package://frcrobot_description/meshes/br_fixed_link_visual.stl"/>
</geometry>
<material name="br_fixed_link_material">
<color rgba="0.40580203232839273664 0.41204827568174379193 0.4259149895098925942 1.0"/>
</material>
</visual>
<collision>
<origin xyz="0 0 0" rpy="0 -0 0" />
<geometry>
<mesh filename="package://frcrobot_description/meshes/br_fixed_link_collision.stl"/>
</geometry>
</collision>
<inertial>
<origin xyz="0.093086953924054055554 -0.0076968875686334982736 0.0064477325071934793455" rpy="0 0 0"/>
<mass value="10.00237711867984256" />
<inertia ixx="0.0072740667010466816822" ixy="-0.0005372416991320313898"  ixz="0.00257934197979136021" iyy="0.010711313332956691816" iyz="-0.0004836411101117216475" izz="0.0072293168828333562864" />
</inertial>
</link>

<link name="br_angle_link">
<visual>
<origin xyz="0 0 0" rpy="0 -0 0" />
<geometry>
<mesh filename="package://frcrobot_description/meshes/br_angle_link_visual.stl"/>
</geometry>
<material name="br_angle_link_material">
<color rgba="0.6267984952905543139 0.64535024166481924635 0.68477270271013168657 1.0"/>
</material>
</visual>
<collision>
<origin xyz="0 0 0" rpy="0 -0 0" />
<geometry>
<mesh filename="package://frcrobot_description/meshes/br_angle_link_collision.stl"/>
</geometry>
</collision>
<inertial>
<origin xyz="0.00065761094785708360758 0.00065772624260718355344 0.01354666940021057725" rpy="0 0 0"/>
<mass value="0.37485540355657037681" />
<inertia ixx="0.00039226399064709051821" ixy="-8.0584943533433187187e-05"  ixz="2.2105941443718480515e-05" iyy="0.00039226841599643850122" iyz="2.2036140493596686487e-05" izz="0.00038236676743388930966" />
</inertial>
</link>

<link name="br_drive_link">
<visual>
<origin xyz="0 0 0" rpy="0 -0 0" />
<geometry>
<mesh filename="package://frcrobot_description/meshes/br_drive_link_visual.stl"/>
</geometry>
<material name="br_drive_link_material">
<color rgba="0.52614927592863802719 0.54556289807692426308 0.58681684514203258374 1.0"/>
</material>
</visual>
<collision>
<origin xyz="0 0 0" rpy="0 -0 0" />
<geometry>
<mesh filename="package://frcrobot_description/meshes/br_drive_link_collision.stl"/>
</geometry>
</collision>
<inertial>
<origin xyz="-0.00029420716981481736998 -0.0002102741524638343767 -0.027662187922789772954" rpy="0 0 0"/>
<mass value="0.23325990258684708989" />
<inertia ixx="0.00015081832600332811117" ixy="-1.398561874512072729e-06"  ixz="4.3273931186669066076e-07" iyy="0.00015177545029262622784" iyz="3.0928503887262179799e-07" izz="0.00024250688465128714686" />
</inertial>
</link>

<joint name="br_drive" type="continuous">
<origin xyz="-0.014718639782432386617 -0.014718639782432596519 0.041331500000000014061" rpy="1.5707963267948990005 0.56629976412908578087 -0.78539816339744417117" />
<parent link="br_angle_link" />
<child link="br_drive_link" />
<axis xyz="0 0 1"/>
<limit effort="1000.0" velocity="200.0" />
<dynamics friction="5.0"/>
<joint_properties friction="5.0"/>
</joint>

<joint name="br_angle" type="continuous">
<origin xyz="0.06667500000000003979 0.0075565000000000354108 -0.019843749999999937828" rpy="-1.570796326794896558 0.75049157835754343182 -2.6965779467394186218e-31" />
<parent link="br_fixed_link" />
<child link="br_angle_link" />
<axis xyz="0 0 1"/>
<limit effort="1000.0" velocity="200.0" />
<dynamics friction="5.0"/>
<joint_properties friction="5.0"/>
</joint>

<joint name="XX1_center" type="fixed">
<origin xyz="-0.23098760000000007064 0.31750000000000000444 0.097205800000000008865" rpy="-1.570796326794896558 -0 -1.570796326794896558" />
<parent link="central_chassis" />
<child link="br_fixed_link" />
<axis xyz="0 0 1"/>
<limit effort="1000.0" velocity="200.0" />
<dynamics friction="5.0"/>
<joint_properties friction="5.0"/>
</joint>

<link name="fr_fixed_link">
<visual>
<origin xyz="0 0 0" rpy="0 -0 0" />
<geometry>
<mesh filename="package://frcrobot_description/meshes/fr_fixed_link_visual.stl"/>
</geometry>
<material name="fr_fixed_link_material">
<color rgba="0.40580203232839251459 0.41204827568174356989 0.42591498950989242767 1.0"/>
</material>
</visual>
<collision>
<origin xyz="0 0 0" rpy="0 -0 0" />
<geometry>
<mesh filename="package://frcrobot_description/meshes/fr_fixed_link_collision.stl"/>
</geometry>
</collision>
<inertial>
<origin xyz="0.093086953924054000042 -0.0076968875686333785777 0.0064477325071934646003" rpy="0 0 0"/>
<mass value="10.002377118679851442" />
<inertia ixx="0.0072740667010466894885" ixy="-0.00053724169913203756975"  ixz="0.0025793419797913480669" iyy="0.01071131333295669355" iyz="-0.00048364111011172636377" izz="0.0072293168828333571538" />
</inertial>
</link>

<link name="fr_angle_link">
<visual>
<origin xyz="0 0 0" rpy="0 -0 0" />
<geometry>
<mesh filename="package://frcrobot_description/meshes/fr_angle_link_visual.stl"/>
</geometry>
<material name="fr_angle_link_material">
<color rgba="0.6267984952905543139 0.6453502416648190243 0.68477270271013179759 1.0"/>
</material>
</visual>
<collision>
<origin xyz="0 0 0" rpy="0 -0 0" />
<geometry>
<mesh filename="package://frcrobot_description/meshes/fr_angle_link_collision.stl"/>
</geometry>
</collision>
<inertial>
<origin xyz="0.0006576109478571829205 0.00065772624260719667229 0.013546669400210677864" rpy="0 0 0"/>
<mass value="0.37485540355657037681" />
<inertia ixx="0.00039226399064709095189" ixy="-8.0584943533433512448e-05"  ixz="2.2105941443718571995e-05" iyy="0.00039226841599643963963" iyz="2.2036140493596828788e-05" izz="0.00038236676743388968913" />
</inertial>
</link>

<link name="fr_drive_link">
<visual>
<origin xyz="0 0 0" rpy="0 -0 0" />
<geometry>
<mesh filename="package://frcrobot_description/meshes/fr_drive_link_visual.stl"/>
</geometry>
<material name="fr_drive_link_material">
<color rgba="0.52614927592863802719 0.54556289807692426308 0.58681684514203258374 1.0"/>
</material>
</visual>
<collision>
<origin xyz="0 0 0" rpy="0 -0 0" />
<geometry>
<mesh filename="package://frcrobot_description/meshes/fr_drive_link_collision.stl"/>
</geometry>
</collision>
<inertial>
<origin xyz="-0.00029420716981483422932 -0.00021027415246389745017 -0.027662187922789727851" rpy="0 0 0"/>
<mass value="0.23325990258684708989" />
<inertia ixx="0.00015081832600332784012" ixy="-1.3985618745120267775e-06"  ixz="4.3273931186671427181e-07" iyy="0.00015177545029262614652" iyz="3.0928503887262523906e-07" izz="0.0002425068846512868216" />
</inertial>
</link>

<joint name="fr_drive" type="continuous">
<origin xyz="-0.014718639782432374474 -0.01471863978243261907 0.041331500000000236106" rpy="1.5707963267949003328 1.2191085435220101463 -0.7853981633974378429" />
<parent link="fr_angle_link" />
<child link="fr_drive_link" />
<axis xyz="0 0 1"/>
<limit effort="1000.0" velocity="200.0" />
<dynamics friction="5.0"/>
<joint_properties friction="5.0"/>
</joint>

<joint name="fr_angle" type="continuous">
<origin xyz="0.066674999999999984279 0.007556500000000021533 -0.019843750000000021094" rpy="1.570796326794896558 0.78539816339745016638 3.1415926535897926719" />
<parent link="fr_fixed_link" />
<child link="fr_angle_link" />
<axis xyz="0 0 1"/>
<limit effort="1000.0" velocity="200.0" />
<dynamics friction="5.0"/>
<joint_properties friction="5.0"/>
</joint>

<joint name="XX2_center" type="fixed">
<origin xyz="-0.31750000000000011546 -0.23098760000000001513 0.097205800000000008865" rpy="-1.570796326794896558 2.8471472759711992776e-46 -1.7483827159451257974e-16" />
<parent link="central_chassis" />
<child link="fr_fixed_link" />
<axis xyz="0 0 1"/>
<limit effort="1000.0" velocity="200.0" />
<dynamics friction="5.0"/>
<joint_properties friction="5.0"/>
</joint>

<link name="fl_fixed_link">
<visual>
<origin xyz="0 0 0" rpy="0 -0 0" />
<geometry>
<mesh filename="package://frcrobot_description/meshes/fl_fixed_link_visual.stl"/>
</geometry>
<material name="fl_fixed_link_material">
<color rgba="0.4058020323283925701 0.41204827568174379193 0.42591498950989248318 1.0"/>
</material>
</visual>
<collision>
<origin xyz="0 0 0" rpy="0 -0 0" />
<geometry>
<mesh filename="package://frcrobot_description/meshes/fl_fixed_link_collision.stl"/>
</geometry>
</collision>
<inertial>
<origin xyz="-0.09258548250719345063 -0.0073158875686334902053 0.0065682039240540154856" rpy="0 0 0"/>
<mass value="10.002377118679847001" />
<inertia ixx="0.0072293168828333580211" ixy="0.00048364111011172018382"  ixz="-0.0025793419797913619447" iyy="0.010711313332956684877" iyz="-0.0005372416991320308477" izz="0.0072740667010466799475" />
</inertial>
</link>

<link name="fl_angle_link">
<visual>
<origin xyz="0 0 0" rpy="0 -0 0" />
<geometry>
<mesh filename="package://frcrobot_description/meshes/fl_angle_link_visual.stl"/>
</geometry>
<material name="fl_angle_link_material">
<color rgba="0.6267984952905543139 0.64535024166481924635 0.68477270271013179759 1.0"/>
</material>
</visual>
<collision>
<origin xyz="0 0 0" rpy="0 -0 0" />
<geometry>
<mesh filename="package://frcrobot_description/meshes/fl_angle_link_collision.stl"/>
</geometry>
</collision>
<inertial>
<origin xyz="0.0018255910263496367713 0.0018257063210997870242 0.013546669400210337858" rpy="0 0 0"/>
<mass value="0.37485540355657037681" />
<inertia ixx="0.0003922639906470910061" ixy="-8.0584943533433241398e-05"  ixz="2.2105941443718080716e-05" iyy="0.00039226841599643871806" iyz="2.2036140493596906715e-05" izz="0.00038236676743388920124" />
</inertial>
</link>

<link name="fl_drive_link">
<visual>
<origin xyz="0 0 0" rpy="0 -0 0" />
<geometry>
<mesh filename="package://frcrobot_description/meshes/fl_drive_link_visual.stl"/>
</geometry>
<material name="fl_drive_link_material">
<color rgba="0.52614927592863802719 0.54556289807692426308 0.58681684514203258374 1.0"/>
</material>
</visual>
<collision>
<origin xyz="0 0 0" rpy="0 -0 0" />
<geometry>
<mesh filename="package://frcrobot_description/meshes/fl_drive_link_collision.stl"/>
</geometry>
</collision>
<inertial>
<origin xyz="-0.00029420716981485959965 -0.00021027415246388191897 -0.027662187922789703565" rpy="0 0 0"/>
<mass value="0.23325990258684708989" />
<inertia ixx="0.00015081832600332784012" ixy="-1.3985618745119539326e-06"  ixz="4.3273931186686377312e-07" iyy="0.00015177545029262617363" iyz="3.09285038872615657e-07" izz="0.00024250688465128714686" />
</inertial>
</link>

<joint name="fl_drive" type="continuous">
<origin xyz="-0.013550659703939711698 -0.013550659703939982315 0.0413314999999997712" rpy="1.5707963267948983344 0.0066490939608964379562 -0.78539816339744317197" />
<parent link="fl_angle_link" />
<child link="fl_drive_link" />
<axis xyz="0 0 1"/>
<limit effort="1000.0" velocity="200.0" />
<dynamics friction="5.0"/>
<joint_properties friction="5.0"/>
</joint>

<joint name="fl_angle" type="continuous">
<origin xyz="-0.066294000000000019579 0.0079375000000000278666 -0.019843749999999993339" rpy="1.570796326794896558 0.82030474843735889934 3.141592653589793116" />
<parent link="fl_fixed_link" />
<child link="fl_angle_link" />
<axis xyz="0 0 1"/>
<limit effort="1000.0" velocity="200.0" />
<dynamics friction="5.0"/>
<joint_properties friction="5.0"/>
</joint>

<joint name="XX3_center" type="fixed">
<origin xyz="0.31749999999999983791 -0.23098760000000001513 0.097205800000000008865" rpy="-1.570796326794896558 -0 -1.7483827159451285091e-16" />
<parent link="central_chassis" />
<child link="fl_fixed_link" />
<axis xyz="0 0 1"/>
<limit effort="1000.0" velocity="200.0" />
<dynamics friction="5.0"/>
<joint_properties friction="5.0"/>
</joint>

<link name="bl_fixed_link">
<visual>
<origin xyz="0 0 0" rpy="0 -0 0" />
<geometry>
<mesh filename="package://frcrobot_description/meshes/bl_fixed_link_visual.stl"/>
</geometry>
<material name="bl_fixed_link_material">
<color rgba="0.40580203232839262562 0.41204827568174373642 0.42591498950989253869 1.0"/>
</material>
</visual>
<collision>
<origin xyz="0 0 0" rpy="0 -0 0" />
<geometry>
<mesh filename="package://frcrobot_description/meshes/bl_fixed_link_collision.stl"/>
</geometry>
</collision>
<inertial>
<origin xyz="0.092705953924053910442 0.0073158875686334650518 -0.0064477325071934064871" rpy="0 0 0"/>
<mass value="10.002377118679847001" />
<inertia ixx="0.0072740667010466782127" ixy="0.00053724169913202889613"  ixz="-0.0025793419797913610773" iyy="0.010711313332956676203" iyz="-0.00048364111011171996698" izz="0.0072293168828333554191" />
</inertial>
</link>

<link name="bl_angle_link">
<visual>
<origin xyz="0 0 0" rpy="0 -0 0" />
<geometry>
<mesh filename="package://frcrobot_description/meshes/bl_angle_link_visual.stl"/>
</geometry>
<material name="bl_angle_link_material">
<color rgba="0.6267984952905543139 0.6453502416648190243 0.68477270271013179759 1.0"/>
</material>
</visual>
<collision>
<origin xyz="0 0 0" rpy="0 -0 0" />
<geometry>
<mesh filename="package://frcrobot_description/meshes/bl_angle_link_collision.stl"/>
</geometry>
</collision>
<inertial>
<origin xyz="0.0006576109478571518039 0.0006577262426071414864 0.01354666940021057725" rpy="0 0 0"/>
<mass value="0.37485540355657037681" />
<inertia ixx="0.00039226399064709062663" ixy="-8.0584943533433431133e-05"  ixz="2.2105941443718582159e-05" iyy="0.00039226841599643860964" iyz="2.2036140493596750861e-05" izz="0.00038236676743388947229" />
</inertial>
</link>

<link name="bl_drive_link">
<visual>
<origin xyz="0 0 0" rpy="0 -0 0" />
<geometry>
<mesh filename="package://frcrobot_description/meshes/bl_drive_link_visual.stl"/>
</geometry>
<material name="bl_drive_link_material">
<color rgba="0.52614927592863802719 0.54556289807692426308 0.58681684514203258374 1.0"/>
</material>
</visual>
<collision>
<origin xyz="0 0 0" rpy="0 -0 0" />
<geometry>
<mesh filename="package://frcrobot_description/meshes/bl_drive_link_collision.stl"/>
</geometry>
</collision>
<inertial>
<origin xyz="-0.00029420716981489136678 -0.00021027415246391230374 -0.027662187922789755606" rpy="0 0 0"/>
<mass value="0.23325990258684708989" />
<inertia ixx="0.00015081832600332784012" ixy="-1.3985618745120320714e-06"  ixz="4.3273931186683327994e-07" iyy="0.00015177545029262606521" iyz="3.0928503887247557892e-07" izz="0.00024250688465128698423" />
</inertial>
</link>

<joint name="bl_drive" type="continuous">
<origin xyz="-0.01471863978243215243 -0.014718639782432601723 0.041331499999999986306" rpy="-1.5707963267948985564 0.47976839601182080797 2.3561944901923439488" />
<parent link="bl_angle_link" />
<child link="bl_drive_link" />
<axis xyz="0 0 1"/>
<limit effort="1000.0" velocity="200.0" />
<dynamics friction="5.0"/>
<joint_properties friction="5.0"/>
</joint>

<joint name="bl_angle" type="continuous">
<origin xyz="0.066294000000000019579 -0.0079375000000001388889 0.019843750000000021094" rpy="1.570796326794896558 0.82030474843733491852 -3.1182876468913807572e-16" />
<parent link="bl_fixed_link" />
<child link="bl_angle_link" />
<axis xyz="0 0 1"/>
<limit effort="1000.0" velocity="200.0" />
<dynamics friction="5.0"/>
<joint_properties friction="5.0"/>
</joint>

<joint name="XX4_center" type="fixed">
<origin xyz="0.31749999999999989342 0.23098759999999995962 0.097205800000000092131" rpy="1.570796326794896558 -2.2204460492411462706e-16 3.141592653589793116" />
<parent link="central_chassis" />
<child link="bl_fixed_link" />
<axis xyz="0 0 1"/>
<limit effort="1000.0" velocity="200.0" />
<dynamics friction="5.0"/>
<joint_properties friction="5.0"/>
</joint>



<gazebo>
    <plugin name="gazebo_frcrobot_plugin" filename="libgazebo_frcrobot_control.so">
        <robotNamespace>/</robotNamespace>
        <robotParam>robot_description</robotParam>
    </plugin>
</gazebo>

</robot>
