<robot name="onshape">
<link name="base_link"></link>
<joint name="base_link_to_base" type="fixed">
<parent link="base_link"/>
<child link="central_chassis" />
<origin rpy="0.0 0 0" xyz="0 0 0"/>
</joint>
<link name="central_chassis">
<visual>
<origin xyz="0 0 0" rpy="0 -0 0" />
<geometry>
<mesh filename="package://frcrobot_description/y2023_urdf/central_chassis_visual.stl"/>
</geometry>
<material name="central_chassis_material">
<color rgba="0.59658581071440286436 0.62025664106601552383 0.63761838421033945057 1.0"/>
</material>
</visual>
<collision>
<origin xyz="0 0 0" rpy="0 -0 0" />
<geometry>
<mesh filename="package://frcrobot_description/y2023_urdf/central_chassis_collision.stl"/>
</geometry>
</collision>
<inertial>
<origin xyz="-0.001927300536847842069 0.086159516777112241104 0.32950095935229994915" rpy="0 0 0"/>
<mass value="7.7787891582795705148" />
<inertia ixx="0.692049321943721929" ixy="0.0020725732451341667348"  ixz="-0.00019563921735655728784" iyy="0.61874181701311536941" iyz="0.11955242865535568864" izz="0.43424100425481654275" />
</inertial>
</link>

<link name="fixed_stage">
<visual>
<origin xyz="0 0 0" rpy="0 -0 0" />
<geometry>
<mesh filename="package://frcrobot_description/y2023_urdf/fixed_stage_visual.stl"/>
</geometry>
<material name="fixed_stage_material">
<color rgba="0.40580203232833966798 0.41204827568168778118 0.42591498950982964455 1.0"/>
</material>
</visual>
<collision>
<origin xyz="0 0 0" rpy="0 -0 0" />
<geometry>
<mesh filename="package://frcrobot_description/y2023_urdf/fixed_stage_collision.stl"/>
</geometry>
</collision>
<inertial>
<origin xyz="0.093086953924036083818 -0.0076968875686517076659 0.0064477325072258284688" rpy="0 0 0"/>
<mass value="2.1102377118690225366" />
<inertia ixx="0.0072740667010526031608" ixy="-0.00053724169913343608213"  ixz="0.0025793419797938564771" iyy="0.010711313332962575998" iyz="-0.00048364111010919496854" izz="0.0072293168828361700079" />
</inertial>
</link>

<link name="first_stage">
<visual>
<origin xyz="0 0 0" rpy="0 -0 0" />
<geometry>
<mesh filename="package://frcrobot_description/y2023_urdf/first_stage_visual.stl"/>
</geometry>
<material name="first_stage_material">
<color rgba="0.62679849529055442492 0.64535024166481924635 0.68477270271013201963 1.0"/>
</material>
</visual>
<collision>
<origin xyz="0 0 0" rpy="0 -0 0" />
<geometry>
<mesh filename="package://frcrobot_description/y2023_urdf/first_stage_collision.stl"/>
</geometry>
</collision>
<inertial>
<origin xyz="0.00065761094785689354694 0.00065772624260732688497 0.013546669400210410716" rpy="0 0 0"/>
<mass value="0.37485540355657037681" />
<inertia ixx="0.00039226399064708553088" ixy="-8.0584943533433810604e-05"  ixz="2.2105941443719405475e-05" iyy="0.00039226841599643492335" iyz="2.2036140493595731034e-05" izz="0.0003823667674338889844" />
</inertial>
</link>

<link name="second_stage">
<visual>
<origin xyz="0 0 0" rpy="0 -0 0" />
<geometry>
<mesh filename="package://frcrobot_description/y2023_urdf/second_stage_visual.stl"/>
</geometry>
<material name="second_stage_material">
<color rgba="0.43962129049865933395 0.48422362538019175782 0.58086036059590284708 1.0"/>
</material>
</visual>
<collision>
<origin xyz="0 0 0" rpy="0 -0 0" />
<geometry>
<mesh filename="package://frcrobot_description/y2023_urdf/second_stage_collision.stl"/>
</geometry>
</collision>
<inertial>
<origin xyz="-0.00060219608071351339324 -0.0004298975173458140773 -0.025814159072832135872" rpy="0 0 0"/>
<mass value="0.34193546654456347111" />
<inertia ixx="0.00025919001370537067715" ixy="-4.3830553719888089097e-06"  ixz="9.5090523028358196318e-07" iyy="0.00026221580444056905804" iyz="6.770447702628630414e-07" izz="0.00043171455134411151336" />
</inertial>
</link>

<joint name="left_front_drive_wheel" type="continuous">
<origin xyz="-0.014718639782432818564 -0.014718639782432485497 0.041331499999999611605" rpy="1.5707963267948974462 0.3547103969677229407 -0.78539816339744616958" />
<parent link="first_stage" />
<child link="second_stage" />
<axis xyz="0 0 1"/>
<limit effort="1" velocity="20" />
<joint_properties friction="0.0"/>
</joint>

<joint name="left_front_angle_wheel" type="continuous">
<origin xyz="0.066674999999999984279 0.0075565000000000354108 -0.019843749999999937828" rpy="-1.5707963267948954478 -0.0013042609915997001487 -9.0564346581562362991e-16" />
<parent link="fixed_stage" />
<child link="first_stage" />
<axis xyz="0 0 1"/>
<limit effort="1" velocity="20" />
<joint_properties friction="0.0"/>
</joint>

<joint name="XX1_center" type="fixed">
<origin xyz="-0.23098760000000007064 0.31750000000000000444 0.097205800000000008865" rpy="-1.570796326794896558 -0 -1.570796326794896558" />
<parent link="central_chassis" />
<child link="fixed_stage" />
<axis xyz="0 0 1"/>
<limit effort="1" velocity="20" />
<joint_properties friction="0.0"/>
</joint>

<link name="fixed_stage_2">
<visual>
<origin xyz="0 0 0" rpy="0 -0 0" />
<geometry>
<mesh filename="package://frcrobot_description/y2023_urdf/fixed_stage_2_visual.stl"/>
</geometry>
<material name="fixed_stage_2_material">
<color rgba="0.40580203232833950144 0.41204827568168744811 0.42591498950982925598 1.0"/>
</material>
</visual>
<collision>
<origin xyz="0 0 0" rpy="0 -0 0" />
<geometry>
<mesh filename="package://frcrobot_description/y2023_urdf/fixed_stage_2_collision.stl"/>
</geometry>
</collision>
<inertial>
<origin xyz="0.093086953924035972796 -0.0076968875686515818985 0.0064477325072258163258" rpy="0 0 0"/>
<mass value="2.1102377118690238689" />
<inertia ixx="0.0072740667010526092323" ixy="-0.00053724169913344323787"  ixz="0.0025793419797938465024" iyy="0.010711313332962589875" iyz="-0.00048364111010919952219" izz="0.0072293168828361734773" />
</inertial>
</link>

<link name="first_stage_2">
<visual>
<origin xyz="0 0 0" rpy="0 -0 0" />
<geometry>
<mesh filename="package://frcrobot_description/y2023_urdf/first_stage_2_visual.stl"/>
</geometry>
<material name="first_stage_2_material">
<color rgba="0.6267984952905543139 0.64535024166481913532 0.68477270271013190861 1.0"/>
</material>
</visual>
<collision>
<origin xyz="0 0 0" rpy="0 -0 0" />
<geometry>
<mesh filename="package://frcrobot_description/y2023_urdf/first_stage_2_collision.stl"/>
</geometry>
</collision>
<inertial>
<origin xyz="0.00065761094785723344432 0.00065772624260738098666 0.01354666940021067266" rpy="0 0 0"/>
<mass value="0.37485540355657043232" />
<inertia ixx="0.00039226399064709111452" ixy="-8.0584943533433851261e-05"  ixz="2.2105941443718226405e-05" iyy="0.00039226841599643969384" iyz="2.2036140493596283299e-05" izz="0.00038236676743388996018" />
</inertial>
</link>

<link name="second_stage_2">
<visual>
<origin xyz="0 0 0" rpy="0 -0 0" />
<geometry>
<mesh filename="package://frcrobot_description/y2023_urdf/second_stage_2_visual.stl"/>
</geometry>
<material name="second_stage_2_material">
<color rgba="0.43962129049865933395 0.48422362538019181333 0.58086036059590284708 1.0"/>
</material>
</visual>
<collision>
<origin xyz="0 0 0" rpy="0 -0 0" />
<geometry>
<mesh filename="package://frcrobot_description/y2023_urdf/second_stage_2_collision.stl"/>
</geometry>
</collision>
<inertial>
<origin xyz="-0.00060219608071357768643 -0.00042989751734580974049 -0.025814159072832118524" rpy="0 0 0"/>
<mass value="0.3419354665445634156" />
<inertia ixx="0.00025919001370537073136" ixy="-4.3830553719887699462e-06"  ixz="9.5090523028355941092e-07" iyy="0.00026221580444056900383" iyz="6.7704477026275324476e-07" izz="0.00043171455134411162178" />
</inertial>
</link>

<joint name="left_back_drive_wheel" type="continuous">
<origin xyz="-0.014718639782431541807 -0.014718639782432388352 0.041331500000000201411" rpy="1.5707963267948981123 -0.10233292597333981666 -0.78539816339744639162" />
<parent link="first_stage_2" />
<child link="second_stage_2" />
<axis xyz="0 0 1"/>
<limit effort="1" velocity="20" />
<joint_properties friction="0.0"/>
</joint>

<joint name="left_back_angle_wheel" type="continuous">
<origin xyz="0.06667500000000003979 0.007556500000000021533 -0.019843749999999965583" rpy="1.570796326794896558 0.74446276911887487859 3.141592653589793116" />
<parent link="fixed_stage_2" />
<child link="first_stage_2" />
<axis xyz="0 0 1"/>
<limit effort="1" velocity="20" />
<joint_properties friction="0.0"/>
</joint>

<joint name="XX2_center" type="fixed">
<origin xyz="-0.31750000000000011546 -0.23098760000000001513 0.097205800000000008865" rpy="-1.570796326794896558 2.8471472759711992776e-46 -1.7483827159451257974e-16" />
<parent link="central_chassis" />
<child link="fixed_stage_2" />
<axis xyz="0 0 1"/>
<limit effort="1" velocity="20" />
<joint_properties friction="0.0"/>
</joint>

<link name="fixed_stage_3">
<visual>
<origin xyz="0 0 0" rpy="0 -0 0" />
<geometry>
<mesh filename="package://frcrobot_description/y2023_urdf/fixed_stage_3_visual.stl"/>
</geometry>
<material name="fixed_stage_3_material">
<color rgba="0.40580203232833939042 0.41204827568168755914 0.425914989509829367 1.0"/>
</material>
</visual>
<collision>
<origin xyz="0 0 0" rpy="0 -0 0" />
<geometry>
<mesh filename="package://frcrobot_description/y2023_urdf/fixed_stage_3_collision.stl"/>
</geometry>
</collision>
<inertial>
<origin xyz="-0.092585482507225730364 -0.0073158875686516978629 0.0065682039240360272705" rpy="0 0 0"/>
<mass value="2.1102377118690234248" />
<inertia ixx="0.0072293168828361769468" ixy="0.00048364111010919301698"  ixz="-0.0025793419797938586455" iyy="0.010711313332962575998" iyz="-0.00053724169913343629897" izz="0.0072740667010526040281" />
</inertial>
</link>

<link name="first_stage_3">
<visual>
<origin xyz="0 0 0" rpy="0 -0 0" />
<geometry>
<mesh filename="package://frcrobot_description/y2023_urdf/first_stage_3_visual.stl"/>
</geometry>
<material name="first_stage_3_material">
<color rgba="0.6267984952905543139 0.64535024166481913532 0.68477270271013201963 1.0"/>
</material>
</visual>
<collision>
<origin xyz="0 0 0" rpy="0 -0 0" />
<geometry>
<mesh filename="package://frcrobot_description/y2023_urdf/first_stage_3_collision.stl"/>
</geometry>
</collision>
<inertial>
<origin xyz="0.0018255910263493997647 0.0018257063211000452811 0.013546669400209765399" rpy="0 0 0"/>
<mass value="0.37485540355657043232" />
<inertia ixx="0.00039226399064707897146" ixy="-8.0584943533434339152e-05"  ixz="2.2105941443719002288e-05" iyy="0.00039226841599642858077" iyz="2.2036140493594995809e-05" izz="0.00038236676743388692441" />
</inertial>
</link>

<link name="second_stage_3">
<visual>
<origin xyz="0 0 0" rpy="0 -0 0" />
<geometry>
<mesh filename="package://frcrobot_description/y2023_urdf/second_stage_3_visual.stl"/>
</geometry>
<material name="second_stage_3_material">
<color rgba="0.43962129049865933395 0.48422362538019175782 0.58086036059590284708 1.0"/>
</material>
</visual>
<collision>
<origin xyz="0 0 0" rpy="0 -0 0" />
<geometry>
<mesh filename="package://frcrobot_description/y2023_urdf/second_stage_3_collision.stl"/>
</geometry>
</collision>
<inertial>
<origin xyz="-0.00060219608071357530119 -0.00042989751734580898155 -0.025814159072832180974" rpy="0 0 0"/>
<mass value="0.34193546654456347111" />
<inertia ixx="0.00025919001370537089399" ixy="-4.3830553719887733343e-06"  ixz="9.509052302837354879e-07" iyy="0.00026221580444056932909" iyz="6.7704477026274106866e-07" izz="0.00043171455134411140494" />
</inertial>
</link>

<joint name="right_back_drive_wheel" type="continuous">
<origin xyz="-0.013550659703940370893 -0.013550659703939815781 0.041331499999998508321" rpy="-1.5707963267948952257 -0.38629807207531591251 2.3561944901923501661" />
<parent link="first_stage_3" />
<child link="second_stage_3" />
<axis xyz="0 0 1"/>
<limit effort="1" velocity="20" />
<joint_properties friction="0.0"/>
</joint>

<joint name="right_back_angle_wheel" type="continuous">
<origin xyz="-0.066293999999999908557 0.0079375000000000278666 -0.019843749999999937828" rpy="1.570796326794896558 -1.3713290209023065724 3.1415926535897726879" />
<parent link="fixed_stage_3" />
<child link="first_stage_3" />
<axis xyz="0 0 1"/>
<limit effort="1" velocity="20" />
<joint_properties friction="0.0"/>
</joint>

<joint name="XX3_center" type="fixed">
<origin xyz="0.31749999999999983791 -0.23098760000000001513 0.097205800000000008865" rpy="-1.570796326794896558 -0 -1.7483827159451285091e-16" />
<parent link="central_chassis" />
<child link="fixed_stage_3" />
<axis xyz="0 0 1"/>
<limit effort="1" velocity="20" />
<joint_properties friction="0.0"/>
</joint>

<link name="fixed_stage_4">
<visual>
<origin xyz="0 0 0" rpy="0 -0 0" />
<geometry>
<mesh filename="package://frcrobot_description/y2023_urdf/fixed_stage_4_visual.stl"/>
</geometry>
<material name="fixed_stage_4_material">
<color rgba="0.40580203232833955695 0.41204827568168755914 0.42591498950982947802 1.0"/>
</material>
</visual>
<collision>
<origin xyz="0 0 0" rpy="0 -0 0" />
<geometry>
<mesh filename="package://frcrobot_description/y2023_urdf/fixed_stage_4_collision.stl"/>
</geometry>
</collision>
<inertial>
<origin xyz="0.092705953924035910951 0.0073158875686516709747 -0.0064477325072257538757" rpy="0 0 0"/>
<mass value="2.1102377118690234248" />
<inertia ixx="0.0072740667010525970892" ixy="0.00053724169913343456425"  ixz="-0.0025793419797938564771" iyy="0.010711313332962567324" iyz="-0.00048364111010919290856" izz="0.0072293168828361717426" />
</inertial>
</link>

<link name="first_stage_4">
<visual>
<origin xyz="0 0 0" rpy="0 -0 0" />
<geometry>
<mesh filename="package://frcrobot_description/y2023_urdf/first_stage_4_visual.stl"/>
</geometry>
<material name="first_stage_4_material">
<color rgba="0.62679849529055442492 0.64535024166481924635 0.68477270271013179759 1.0"/>
</material>
</visual>
<collision>
<origin xyz="0 0 0" rpy="0 -0 0" />
<geometry>
<mesh filename="package://frcrobot_description/y2023_urdf/first_stage_4_collision.stl"/>
</geometry>
</collision>
<inertial>
<origin xyz="0.00065761094785712263886 0.00065772624260720816483 0.013546669400210601536" rpy="0 0 0"/>
<mass value="0.37485540355657037681" />
<inertia ixx="0.00039226399064709035558" ixy="-8.058494353343336337e-05"  ixz="2.2105941443718311109e-05" iyy="0.00039226841599643860964" iyz="2.2036140493596618724e-05" izz="0.00038236676743388930966" />
</inertial>
</link>

<link name="second_stage_4">
<visual>
<origin xyz="0 0 0" rpy="0 -0 0" />
<geometry>
<mesh filename="package://frcrobot_description/y2023_urdf/second_stage_4_visual.stl"/>
</geometry>
<material name="second_stage_4_material">
<color rgba="0.43962129049865933395 0.48422362538019175782 0.58086036059590284708 1.0"/>
</material>
</visual>
<collision>
<origin xyz="0 0 0" rpy="0 -0 0" />
<geometry>
<mesh filename="package://frcrobot_description/y2023_urdf/second_stage_4_collision.stl"/>
</geometry>
</collision>
<inertial>
<origin xyz="-0.00060219608071350417752 -0.00042989751734580567474 -0.025814159072832139341" rpy="0 0 0"/>
<mass value="0.34193546654456347111" />
<inertia ixx="0.00025919001370537062294" ixy="-4.3830553719888029805e-06"  ixz="9.5090523028352669428e-07" iyy="0.00026221580444056889541" iyz="6.7704477026273461003e-07" izz="0.00043171455134411135073" />
</inertial>
</link>

<joint name="right_front_drive_wheel" type="continuous">
<origin xyz="-0.014718639782432263452 -0.014718639782432541008 0.041331500000000041817" rpy="-1.5707963267948994446 0.53105430610586668028 2.3561944901923461693" />
<parent link="first_stage_4" />
<child link="second_stage_4" />
<axis xyz="0 0 1"/>
<limit effort="1" velocity="20" />
<joint_properties friction="0.0"/>
</joint>

<joint name="right_front_angle_wheel" type="continuous">
<origin xyz="0.066293999999999908557 -0.0079375000000000972555 0.019843750000000076605" rpy="-1.570796326794896558 1.2358944559116720185 3.141592653589793116" />
<parent link="fixed_stage_4" />
<child link="first_stage_4" />
<axis xyz="0 0 1"/>
<limit effort="1" velocity="20" />
<joint_properties friction="0.0"/>
</joint>

<joint name="XX4_center" type="fixed">
<origin xyz="0.31749999999999989342 0.23098759999999995962 0.097205800000000092131" rpy="1.570796326794896558 -2.2204460492411462706e-16 3.141592653589793116" />
<parent link="central_chassis" />
<child link="fixed_stage_4" />
<axis xyz="0 0 1"/>
<limit effort="1" velocity="20" />
<joint_properties friction="0.0"/>
</joint>


</robot>
